[2024-12-30T08:49:50.083+0000] {taskinstance.py:1165} INFO - Dependencies all met for <TaskInstance: xcom_dag.t2 manual__2024-12-30T08:49:48.303768+00:00 [queued]>
[2024-12-30T08:49:50.090+0000] {taskinstance.py:1165} INFO - Dependencies all met for <TaskInstance: xcom_dag.t2 manual__2024-12-30T08:49:48.303768+00:00 [queued]>
[2024-12-30T08:49:50.090+0000] {taskinstance.py:1362} INFO - 
--------------------------------------------------------------------------------
[2024-12-30T08:49:50.090+0000] {taskinstance.py:1363} INFO - Starting attempt 1 of 1
[2024-12-30T08:49:50.090+0000] {taskinstance.py:1364} INFO - 
--------------------------------------------------------------------------------
[2024-12-30T08:49:50.103+0000] {taskinstance.py:1383} INFO - Executing <Task(PythonOperator): t2> on 2024-12-30 08:49:48.303768+00:00
[2024-12-30T08:49:50.107+0000] {standard_task_runner.py:55} INFO - Started process 850 to run task
[2024-12-30T08:49:50.110+0000] {standard_task_runner.py:82} INFO - Running: ['***', 'tasks', 'run', 'xcom_dag', 't2', 'manual__2024-12-30T08:49:48.303768+00:00', '--job-id', '43', '--raw', '--subdir', 'DAGS_FOLDER/xcom_dag.py', '--cfg-path', '/tmp/tmpduzhhfw4']
[2024-12-30T08:49:50.110+0000] {standard_task_runner.py:83} INFO - Job 43: Subtask t2
[2024-12-30T08:49:50.143+0000] {task_command.py:376} INFO - Running <TaskInstance: xcom_dag.t2 manual__2024-12-30T08:49:48.303768+00:00 [running]> on host 183ed7d37d5f
[2024-12-30T08:49:50.182+0000] {taskinstance.py:1592} INFO - Exporting the following env vars:
AIRFLOW_CTX_DAG_OWNER=***
AIRFLOW_CTX_DAG_ID=xcom_dag
AIRFLOW_CTX_TASK_ID=t2
AIRFLOW_CTX_EXECUTION_DATE=2024-12-30T08:49:48.303768+00:00
AIRFLOW_CTX_TRY_NUMBER=1
AIRFLOW_CTX_DAG_RUN_ID=manual__2024-12-30T08:49:48.303768+00:00
[2024-12-30T08:49:50.183+0000] {taskinstance.py:1851} ERROR - Task failed with exception
Traceback (most recent call last):
  File "/home/airflow/.local/lib/python3.7/site-packages/airflow/operators/python.py", line 175, in execute
    return_value = self.execute_callable()
  File "/home/airflow/.local/lib/python3.7/site-packages/airflow/operators/python.py", line 193, in execute_callable
    return self.python_callable(*self.op_args, **self.op_kwargs)
  File "/opt/airflow/dags/xcom_dag.py", line 13, in _t2
    print(ti.xcom_pull(key='my_key', task_id='t1'))
  File "/home/airflow/.local/lib/python3.7/site-packages/airflow/utils/session.py", line 75, in wrapper
    return func(*args, session=session, **kwargs)
TypeError: xcom_pull() got an unexpected keyword argument 'task_id'
[2024-12-30T08:49:50.187+0000] {taskinstance.py:1406} INFO - Marking task as FAILED. dag_id=xcom_dag, task_id=t2, execution_date=20241230T084948, start_date=20241230T084950, end_date=20241230T084950
[2024-12-30T08:49:50.192+0000] {standard_task_runner.py:105} ERROR - Failed to execute job 43 for task t2 (xcom_pull() got an unexpected keyword argument 'task_id'; 850)
[2024-12-30T08:49:50.208+0000] {local_task_job.py:164} INFO - Task exited with return code 1
[2024-12-30T08:49:50.223+0000] {local_task_job.py:273} INFO - 0 downstream tasks scheduled from follow-on schedule check
