[2024-12-30T04:49:07.005+0000] {taskinstance.py:1165} INFO - Dependencies all met for <TaskInstance: user_processing.create_table scheduled__2024-12-29T00:00:00+00:00 [queued]>
[2024-12-30T04:49:07.009+0000] {taskinstance.py:1165} INFO - Dependencies all met for <TaskInstance: user_processing.create_table scheduled__2024-12-29T00:00:00+00:00 [queued]>
[2024-12-30T04:49:07.009+0000] {taskinstance.py:1362} INFO - 
--------------------------------------------------------------------------------
[2024-12-30T04:49:07.009+0000] {taskinstance.py:1363} INFO - Starting attempt 1 of 1
[2024-12-30T04:49:07.009+0000] {taskinstance.py:1364} INFO - 
--------------------------------------------------------------------------------
[2024-12-30T04:49:07.015+0000] {taskinstance.py:1383} INFO - Executing <Task(PostgresOperator): create_table> on 2024-12-29 00:00:00+00:00
[2024-12-30T04:49:07.018+0000] {standard_task_runner.py:55} INFO - Started process 139 to run task
[2024-12-30T04:49:07.020+0000] {standard_task_runner.py:82} INFO - Running: ['***', 'tasks', 'run', 'user_processing', 'create_table', 'scheduled__2024-12-29T00:00:00+00:00', '--job-id', '3', '--raw', '--subdir', 'DAGS_FOLDER/user_processing.py', '--cfg-path', '/tmp/tmpsrx7zmk2']
[2024-12-30T04:49:07.021+0000] {standard_task_runner.py:83} INFO - Job 3: Subtask create_table
[2024-12-30T04:49:07.049+0000] {task_command.py:376} INFO - Running <TaskInstance: user_processing.create_table scheduled__2024-12-29T00:00:00+00:00 [running]> on host d9d34418064c
[2024-12-30T04:49:07.078+0000] {taskinstance.py:1592} INFO - Exporting the following env vars:
AIRFLOW_CTX_DAG_OWNER=***
AIRFLOW_CTX_DAG_ID=user_processing
AIRFLOW_CTX_TASK_ID=create_table
AIRFLOW_CTX_EXECUTION_DATE=2024-12-29T00:00:00+00:00
AIRFLOW_CTX_TRY_NUMBER=1
AIRFLOW_CTX_DAG_RUN_ID=scheduled__2024-12-29T00:00:00+00:00
[2024-12-30T04:49:07.086+0000] {taskinstance.py:1851} ERROR - Task failed with exception
Traceback (most recent call last):
  File "/home/airflow/.local/lib/python3.7/site-packages/airflow/providers/postgres/operators/postgres.py", line 94, in execute
    self.hook.run(self.sql, self.autocommit, parameters=self.parameters)
  File "/home/airflow/.local/lib/python3.7/site-packages/airflow/providers/common/sql/hooks/sql.py", line 288, in run
    with closing(self.get_conn()) as conn:
  File "/home/airflow/.local/lib/python3.7/site-packages/airflow/providers/postgres/hooks/postgres.py", line 88, in get_conn
    conn = deepcopy(self.connection or self.get_connection(conn_id))
  File "/home/airflow/.local/lib/python3.7/site-packages/airflow/hooks/base.py", line 70, in get_connection
    conn = Connection.get_connection_from_secrets(conn_id)
  File "/home/airflow/.local/lib/python3.7/site-packages/airflow/models/connection.py", line 432, in get_connection_from_secrets
    raise AirflowNotFoundException(f"The conn_id `{conn_id}` isn't defined")
airflow.exceptions.AirflowNotFoundException: The conn_id `postgres` isn't defined
[2024-12-30T04:49:07.088+0000] {taskinstance.py:1406} INFO - Marking task as FAILED. dag_id=user_processing, task_id=create_table, execution_date=20241229T000000, start_date=20241230T044907, end_date=20241230T044907
[2024-12-30T04:49:07.093+0000] {standard_task_runner.py:105} ERROR - Failed to execute job 3 for task create_table (The conn_id `postgres` isn't defined; 139)
[2024-12-30T04:49:07.121+0000] {local_task_job.py:164} INFO - Task exited with return code 1
[2024-12-30T04:49:07.137+0000] {local_task_job.py:273} INFO - 0 downstream tasks scheduled from follow-on schedule check
