[2024-12-30T08:49:48.236+0000] {taskinstance.py:1165} INFO - Dependencies all met for <TaskInstance: xcom_dag.t2 scheduled__2024-12-29T00:00:00+00:00 [queued]>
[2024-12-30T08:49:48.240+0000] {taskinstance.py:1165} INFO - Dependencies all met for <TaskInstance: xcom_dag.t2 scheduled__2024-12-29T00:00:00+00:00 [queued]>
[2024-12-30T08:49:48.241+0000] {taskinstance.py:1362} INFO - 
--------------------------------------------------------------------------------
[2024-12-30T08:49:48.241+0000] {taskinstance.py:1363} INFO - Starting attempt 1 of 1
[2024-12-30T08:49:48.241+0000] {taskinstance.py:1364} INFO - 
--------------------------------------------------------------------------------
[2024-12-30T08:49:48.247+0000] {taskinstance.py:1383} INFO - Executing <Task(PythonOperator): t2> on 2024-12-29 00:00:00+00:00
[2024-12-30T08:49:48.249+0000] {standard_task_runner.py:55} INFO - Started process 846 to run task
[2024-12-30T08:49:48.251+0000] {standard_task_runner.py:82} INFO - Running: ['***', 'tasks', 'run', 'xcom_dag', 't2', 'scheduled__2024-12-29T00:00:00+00:00', '--job-id', '41', '--raw', '--subdir', 'DAGS_FOLDER/xcom_dag.py', '--cfg-path', '/tmp/tmppt_rztof']
[2024-12-30T08:49:48.252+0000] {standard_task_runner.py:83} INFO - Job 41: Subtask t2
[2024-12-30T08:49:48.277+0000] {task_command.py:376} INFO - Running <TaskInstance: xcom_dag.t2 scheduled__2024-12-29T00:00:00+00:00 [running]> on host 183ed7d37d5f
[2024-12-30T08:49:48.314+0000] {taskinstance.py:1592} INFO - Exporting the following env vars:
AIRFLOW_CTX_DAG_OWNER=***
AIRFLOW_CTX_DAG_ID=xcom_dag
AIRFLOW_CTX_TASK_ID=t2
AIRFLOW_CTX_EXECUTION_DATE=2024-12-29T00:00:00+00:00
AIRFLOW_CTX_TRY_NUMBER=1
AIRFLOW_CTX_DAG_RUN_ID=scheduled__2024-12-29T00:00:00+00:00
[2024-12-30T08:49:48.314+0000] {taskinstance.py:1851} ERROR - Task failed with exception
Traceback (most recent call last):
  File "/home/airflow/.local/lib/python3.7/site-packages/airflow/operators/python.py", line 175, in execute
    return_value = self.execute_callable()
  File "/home/airflow/.local/lib/python3.7/site-packages/airflow/operators/python.py", line 193, in execute_callable
    return self.python_callable(*self.op_args, **self.op_kwargs)
  File "/opt/airflow/dags/xcom_dag.py", line 13, in _t2
    print(ti.xcom_pull(key='my_key', task_id='t1'))
  File "/home/airflow/.local/lib/python3.7/site-packages/airflow/utils/session.py", line 75, in wrapper
    return func(*args, session=session, **kwargs)
TypeError: xcom_pull() got an unexpected keyword argument 'task_id'
[2024-12-30T08:49:48.319+0000] {taskinstance.py:1406} INFO - Marking task as FAILED. dag_id=xcom_dag, task_id=t2, execution_date=20241229T000000, start_date=20241230T084948, end_date=20241230T084948
[2024-12-30T08:49:48.325+0000] {standard_task_runner.py:105} ERROR - Failed to execute job 41 for task t2 (xcom_pull() got an unexpected keyword argument 'task_id'; 846)
[2024-12-30T08:49:48.350+0000] {local_task_job.py:164} INFO - Task exited with return code 1
[2024-12-30T08:49:48.367+0000] {local_task_job.py:273} INFO - 0 downstream tasks scheduled from follow-on schedule check
